Workbook

Sheet Dashboard
A1: DASHBOARD DE VENDAS 2024
A3: Dados fictícios de exemplo — período: jan/2024 a dez/2024. Atualize a aba 'Dados' para refletir números reais.
A5: RECEITA TOTAL | D5: PEDIDOS | G5: TICKET MÉDIO | J5: UNIDADES VENDIDAS
A6: =SUM(Dados!I2:I321) -> 1078872 | D6: =COUNTA(Dados!A2:A321) -> 320 | G6: =SUM(Dados!I2:I321)/COUNTA(Dados!A2:A321) -> 3371.475 | J6: =SUM(Dados!G2:G321) -> 2189
A9: Evolução Mensal, Regiões, Categorias e Ranking

Sheet Dados
A1: ID Pedido | B1: Data | C1: Vendedor | D1: Região | E1: Categoria | F1: Produto | G1: Quantidade | H1: Preço Unitário | I1: Valor Total | J1: Mês
A2: 1023 | B2: 2024-01-01 | C2: Carla Dias | D2: Sul | E2: Papelaria | F2: Kit Canetas | G2: 6 | H2: 23.06 | I2: =G2*H2 -> 138.36 | J2: =YEAR(B2)*100+MONTH(B2) -> 202401
A3: 1039 | B3: 2024-01-02 | C3: Carla Dias | D3: Centro-Oeste | E3: Eletrodomésticos | F3: Liquidificador | G3: 8 | H3: 166.47 | I3: =G3*H3 -> 1331.76 | J3: =YEAR(B3)*100+MONTH(B3) -> 202401
A4: 1125 | B4: 2024-01-02 | C4: Carla Dias | D4: Sudeste | E4: Eletrodomésticos | F4: Liquidificador | G4: 8 | H4: 161.54 | I4: =G4*H4 -> 1292.32 | J4: =YEAR(B4)*100+MONTH(B4) -> 202401
A5: 1047 | B5: 2024-01-05 | C5: Ana Souza | D5: Norte | E5: Eletrodomésticos | F5: Ventilador | G5: 2 | H5: 199.46 | I5: =G5*H5 -> 398.92 | J5: =YEAR(B5)*100+MONTH(B5) -> 202401
A6: 1102 | B6: 2024-01-07 | C6: Fábio Nunes | D6: Centro-Oeste | E6: Eletrodomésticos | F6: Liquidificador | G6: 6 | H6: 149.4 | I6: =G6*H6 -> 896.4 | J6: =YEAR(B6)*100+MONTH(B6) -> 202401
A7: 1118 | B7: 2024-01-07 | C7: Bruno Lima | D7: Sudeste | E7: Papelaria | F7: Kit Canetas | G7: 6 | H7: 24.56 | I7: =G7*H7 -> 147.36 | J7: =YEAR(B7)*100+MONTH(B7) -> 202401
A8: 1110 | B8: 2024-01-09 | C8: Bruno Lima | D8: Nordeste | E8: Eletrônicos | F8: Fone Bluetooth | G8: 12 | H8: 142.32 | I8: =G8*H8 -> 1707.84 | J8: =YEAR(B8)*100+MONTH(B8) -> 202401
A9: 1254 | B9: 2024-01-09 | C9: Ana Souza | D9: Norte | E9: Móveis | F9: Estante | G9: 7 | H9: 356.69 | I9: =G9*H9 -> 2496.83 | J9: =YEAR(B9)*100+MONTH(B9) -> 202401
A10: 1315 | B10: 2024-01-10 | C10: Fábio Nunes | D10: Sul | E10: Eletrodomésticos | F10: Liquidificador | G10: 7 | H10: 155.91 | I10: =G10*H10 -> 1091.37 | J10: =YEAR(B10)*100+MONTH(B10) -> 202401
A11: 1132 | B11: 2024-01-11 | C11: Diego Alves | D11: Norte | E11: Papelaria | F11: Agenda | G11: 3 | H11: 37.01 | I11: =G11*H11 -> 111.03 | J11: =YEAR(B11)*100+MONTH(B11) -> 202401
A12: 1247 | B12: 2024-01-14 | C12: Bruno Lima | D12: Centro-Oeste | E12: Eletrodomésticos | F12: Cafeteira | G12: 6 | H12: 213.74 | I12: =G12*H12 -> 1282.44 | J12: =YEAR(B12)*100+MONTH(B12) -> 202401
A13: 1281 | B13: 2024-01-14 | C13: Elaine Rocha | D13: Sul | E13: Papelaria | F13: Agenda | G13: 8 | H13: 39.78 | I13: =G13*H13 -> 318.24 | J13: =YEAR(B13)*100+MONTH(B13) -> 202401
... A321: 1027 | B321: 2024-12-31 | C321: Carla Dias | D321: Centro-Oeste | E321: Papelaria | F321: Kit Canetas | G321: 11 | H321: 26.23 | I321: =G321*H321 -> 288.53 | J321: =YEAR(B321)*100+MONTH(B321) -> 202412

Sheet Análise
A1: Vendas por Mês
A2: Mês | B2: Receita | C2: Pedidos | D2: Chave
A3: jan/24 | B3: =SUMIF(Dados!$J$2:$J$321,D3,Dados!$I$2:$I$321) -> 51480.56 | C3: =COUNTIF(Dados!$J$2:$J$321,D3) -> 27 | D3: 202401
A4: fev/24 | B4: =SUMIF(Dados!$J$2:$J$321,D4,Dados!$I$2:$I$321) -> 64042.62 | C4: =COUNTIF(Dados!$J$2:$J$321,D4) -> 25 | D4: 202402
A5: mar/24 | B5: =SUMIF(Dados!$J$2:$J$321,D5,Dados!$I$2:$I$321) -> 61096.91 | C5: =COUNTIF(Dados!$J$2:$J$321,D5) -> 27 | D5: 202403
A6: abr/24 | B6: =SUMIF(Dados!$J$2:$J$321,D6,Dados!$I$2:$I$321) -> 49857.97 | C6: =COUNTIF(Dados!$J$2:$J$321,D6) -> 25 | D6: 202404
A7: mai/24 | B7: =SUMIF(Dados!$J$2:$J$321,D7,Dados!$I$2:$I$321) -> 119765.86 | C7: =COUNTIF(Dados!$J$2:$J$321,D7) -> 30 | D7: 202405
A8: jun/24 | B8: =SUMIF(Dados!$J$2:$J$321,D8,Dados!$I$2:$I$321) -> 84387.81 | C8: =COUNTIF(Dados!$J$2:$J$321,D8) -> 26 | D8: 202406
A9: jul/24 | B9: =SUMIF(Dados!$J$2:$J$321,D9,Dados!$I$2:$I$321) -> 82219.73 | C9: =COUNTIF(Dados!$J$2:$J$321,D9) -> 36 | D9: 202407
A10: ago/24 | B10: =SUMIF(Dados!$J$2:$J$321,D10,Dados!$I$2:$I$321) -> 82631.74 | C10: =COUNTIF(Dados!$J$2:$J$321,D10) -> 21 | D10: 202408
A11: set/24 | B11: =SUMIF(Dados!$J$2:$J$321,D11,Dados!$I$2:$I$321) -> 47679.82 | C11: =COUNTIF(Dados!$J$2:$J$321,D11) -> 16 | D11: 202409
A12: out/24 | B12: =SUMIF(Dados!$J$2:$J$321,D12,Dados!$I$2:$I$321) -> 198558.6 | C12: =COUNTIF(Dados!$J$2:$J$321,D12) -> 28 | D12: 202410
A13: nov/24 | B13: =SUMIF(Dados!$J$2:$J$321,D13,Dados!$I$2:$I$321) -> 185837.48 | C13: =COUNTIF(Dados!$J$2:$J$321,D13) -> 36 | D13: 202411
A14: dez/24 | B14: =SUMIF(Dados!$J$2:$J$321,D14,Dados!$I$2:$I$321) -> 51312.89 | C14: =COUNTIF(Dados!$J$2:$J$321,D14) -> 23 | D14: 202412
A17: Vendas por Região
A18: Região | B18: Receita
A19: Centro-Oeste | B19: =SUMIF(Dados!$D$2:$D$321,A19,Dados!$I$2:$I$321) -> 231233.99
A20: Nordeste | B20: =SUMIF(Dados!$D$2:$D$321,A20,Dados!$I$2:$I$321) -> 219465.79
A21: Norte | B21: =SUMIF(Dados!$D$2:$D$321,A21,Dados!$I$2:$I$321) -> 230502.65
A22: Sudeste | B22: =SUMIF(Dados!$D$2:$D$321,A22,Dados!$I$2:$I$321) -> 212229.56
A23: Sul | B23: =SUMIF(Dados!$D$2:$D$321,A23,Dados!$I$2:$I$321) -> 185440
A26: Vendas por Categoria
A27: Categoria | B27: Receita
A28: Eletrodomésticos | B28: =SUMIF(Dados!$E$2:$E$321,A28,Dados!$I$2:$I$321) -> 100839.95
A29: Eletrônicos | B29: =SUMIF(Dados!$E$2:$E$321,A29,Dados!$I$2:$I$321) -> 675355.61
A30: Móveis | B30: =SUMIF(Dados!$E$2:$E$321,A30,Dados!$I$2:$I$321) -> 288548.95
A31: Papelaria | B31: =SUMIF(Dados!$E$2:$E$321,A31,Dados!$I$2:$I$321) -> 14127.48
A34: Ranking de Vendedores
A35: Vendedor | B35: Receita | C35: Pedidos | D35: Ticket Médio
A36: Ana Souza | B36: =SUMIF(Dados!$C$2:$C$321,A36,Dados!$I$2:$I$321) -> 142375.54 | C36: =COUNTIF(Dados!$C$2:$C$321,A36) -> 36 | D36: =IFERROR(B36/C36,0) -> 3954.8761
A37: Bruno Lima | B37: =SUMIF(Dados!$C$2:$C$321,A37,Dados!$I$2:$I$321) -> 214665.31 | C37: =COUNTIF(Dados!$C$2:$C$321,A37) -> 62 | D37: =IFERROR(B37/C37,0) -> 3462.3437
A38: Carla Dias | B38: =SUMIF(Dados!$C$2:$C$321,A38,Dados!$I$2:$I$321) -> 193790.86 | C38: =COUNTIF(Dados!$C$2:$C$321,A38) -> 52 | D38: =IFERROR(B38/C38,0) -> 3726.7473
A39: Diego Alves | B39: =SUMIF(Dados!$C$2:$C$321,A39,Dados!$I$2:$I$321) -> 138858.88 | C39: =COUNTIF(Dados!$C$2:$C$321,A39) -> 50 | D39: =IFERROR(B39/C39,0) -> 2777.1776
A40: Elaine Rocha | B40: =SUMIF(Dados!$C$2:$C$321,A40,Dados!$I$2:$I$321) -> 203141.76 | C40: =COUNTIF(Dados!$C$2:$C$321,A40) -> 61 | D40: =IFERROR(B40/C40,0) -> 3330.1928
A41: Fábio Nunes | B41: =SUMIF(Dados!$C$2:$C$321,A41,Dados!$I$2:$I$321) -> 186039.64 | C41: =COUNTIF(Dados!$C$2:$C$321,A41) -> 59 | D41: =IFERROR(B41/C41,0) -> 3153.2142
A44: Vendas por Produto
A45: Produto | B45: Receita | C45: Quantidade
A46: Agenda | B46: =SUMIF(Dados!$F$2:$F$321,A46,Dados!$I$2:$I$321) -> 7985.8 | C46: =SUMIF(Dados!$F$2:$F$321,A46,Dados!$G$2:$G$321) -> 200
A47: Cadeira Escritório | B47: =SUMIF(Dados!$F$2:$F$321,A47,Dados!$I$2:$I$321) -> 82143.51 | C47: =SUMIF(Dados!$F$2:$F$321,A47,Dados!$G$2:$G$321) -> 186
A48: Caderno | B48: =SUMIF(Dados!$F$2:$F$321,A48,Dados!$I$2:$I$321) -> 3048.27 | C48: =SUMIF(Dados!$F$2:$F$321,A48,Dados!$G$2:$G$321) -> 209
...
